School: 西南科技大学
Timestamp: 20250509_234151
Error Message: 获取页面失败 (url: https://graduate.swust.edu.cn/): HTTPSConnectionPool(host='graduate.swust.edu.cn', port=443): Max retries exceeded with url: / (Caused by NameResolutionError("<urllib3.connection.HTTPSConnection object at 0x1105187d0>: Failed to resolve 'graduate.swust.edu.cn' ([Errno 8] nodename nor servname provided, or not known)"))

Exception Type: ConnectionError
Exception Details: HTTPSConnectionPool(host='graduate.swust.edu.cn', port=443): Max retries exceeded with url: / (Caused by NameResolutionError("<urllib3.connection.HTTPSConnection object at 0x1105187d0>: Failed to resolve 'graduate.swust.edu.cn' ([Errno 8] nodename nor servname provided, or not known)"))

Traceback:
Traceback (most recent call last):
  File "/Users/mac/WorkSpace/考研推荐系统/.venv/lib/python3.13/site-packages/urllib3/connection.py", line 198, in _new_conn
    sock = connection.create_connection(
        (self._dns_host, self.port),
    ...<2 lines>...
        socket_options=self.socket_options,
    )
  File "/Users/mac/WorkSpace/考研推荐系统/.venv/lib/python3.13/site-packages/urllib3/util/connection.py", line 60, in create_connection
    for res in socket.getaddrinfo(host, port, family, socket.SOCK_STREAM):
               ~~~~~~~~~~~~~~~~~~^^^^^^^^^^^^^^^^^^^^^^^^^^^^^^^^^^^^^^^^
  File "/opt/homebrew/Cellar/python@3.13/3.13.3/Frameworks/Python.framework/Versions/3.13/lib/python3.13/socket.py", line 977, in getaddrinfo
    for res in _socket.getaddrinfo(host, port, family, type, proto, flags):
               ~~~~~~~~~~~~~~~~~~~^^^^^^^^^^^^^^^^^^^^^^^^^^^^^^^^^^^^^^^^
socket.gaierror: [Errno 8] nodename nor servname provided, or not known

The above exception was the direct cause of the following exception:

Traceback (most recent call last):
  File "/Users/mac/WorkSpace/考研推荐系统/.venv/lib/python3.13/site-packages/urllib3/connectionpool.py", line 787, in urlopen
    response = self._make_request(
        conn,
    ...<10 lines>...
        **response_kw,
    )
  File "/Users/mac/WorkSpace/考研推荐系统/.venv/lib/python3.13/site-packages/urllib3/connectionpool.py", line 488, in _make_request
    raise new_e
  File "/Users/mac/WorkSpace/考研推荐系统/.venv/lib/python3.13/site-packages/urllib3/connectionpool.py", line 464, in _make_request
    self._validate_conn(conn)
    ~~~~~~~~~~~~~~~~~~~^^^^^^
  File "/Users/mac/WorkSpace/考研推荐系统/.venv/lib/python3.13/site-packages/urllib3/connectionpool.py", line 1093, in _validate_conn
    conn.connect()
    ~~~~~~~~~~~~^^
  File "/Users/mac/WorkSpace/考研推荐系统/.venv/lib/python3.13/site-packages/urllib3/connection.py", line 704, in connect
    self.sock = sock = self._new_conn()
                       ~~~~~~~~~~~~~~^^
  File "/Users/mac/WorkSpace/考研推荐系统/.venv/lib/python3.13/site-packages/urllib3/connection.py", line 205, in _new_conn
    raise NameResolutionError(self.host, self, e) from e
urllib3.exceptions.NameResolutionError: <urllib3.connection.HTTPSConnection object at 0x105f5b9d0>: Failed to resolve 'graduate.swust.edu.cn' ([Errno 8] nodename nor servname provided, or not known)

The above exception was the direct cause of the following exception:

Traceback (most recent call last):
  File "/Users/mac/WorkSpace/考研推荐系统/.venv/lib/python3.13/site-packages/requests/adapters.py", line 667, in send
    resp = conn.urlopen(
        method=request.method,
    ...<9 lines>...
        chunked=chunked,
    )
  File "/Users/mac/WorkSpace/考研推荐系统/.venv/lib/python3.13/site-packages/urllib3/connectionpool.py", line 841, in urlopen
    retries = retries.increment(
        method, url, error=new_e, _pool=self, _stacktrace=sys.exc_info()[2]
    )
  File "/Users/mac/WorkSpace/考研推荐系统/.venv/lib/python3.13/site-packages/urllib3/util/retry.py", line 519, in increment
    raise MaxRetryError(_pool, url, reason) from reason  # type: ignore[arg-type]
    ^^^^^^^^^^^^^^^^^^^^^^^^^^^^^^^^^^^^^^^^^^^^^^^^^^^
urllib3.exceptions.MaxRetryError: HTTPSConnectionPool(host='graduate.swust.edu.cn', port=443): Max retries exceeded with url: / (Caused by NameResolutionError("<urllib3.connection.HTTPSConnection object at 0x105f5b9d0>: Failed to resolve 'graduate.swust.edu.cn' ([Errno 8] nodename nor servname provided, or not known)"))

During handling of the above exception, another exception occurred:

Traceback (most recent call last):
  File "/Users/mac/WorkSpace/考研推荐系统/utils/scraper.py", line 270, in fetch_page
    response = requests.get(url, headers=headers, timeout=REQUEST_TIMEOUT, verify=False)
  File "/Users/mac/WorkSpace/考研推荐系统/.venv/lib/python3.13/site-packages/requests/api.py", line 73, in get
    return request("get", url, params=params, **kwargs)
  File "/Users/mac/WorkSpace/考研推荐系统/.venv/lib/python3.13/site-packages/requests/api.py", line 59, in request
    return session.request(method=method, url=url, **kwargs)
           ~~~~~~~~~~~~~~~^^^^^^^^^^^^^^^^^^^^^^^^^^^^^^^^^^
  File "/Users/mac/WorkSpace/考研推荐系统/.venv/lib/python3.13/site-packages/requests/sessions.py", line 589, in request
    resp = self.send(prep, **send_kwargs)
  File "/Users/mac/WorkSpace/考研推荐系统/.venv/lib/python3.13/site-packages/requests/sessions.py", line 703, in send
    r = adapter.send(request, **kwargs)
  File "/Users/mac/WorkSpace/考研推荐系统/.venv/lib/python3.13/site-packages/requests/adapters.py", line 700, in send
    raise ConnectionError(e, request=request)
requests.exceptions.ConnectionError: HTTPSConnectionPool(host='graduate.swust.edu.cn', port=443): Max retries exceeded with url: / (Caused by NameResolutionError("<urllib3.connection.HTTPSConnection object at 0x105f5b9d0>: Failed to resolve 'graduate.swust.edu.cn' ([Errno 8] nodename nor servname provided, or not known)"))

During handling of the above exception, another exception occurred:

Traceback (most recent call last):
  File "/Users/mac/WorkSpace/考研推荐系统/.venv/lib/python3.13/site-packages/urllib3/connection.py", line 198, in _new_conn
    sock = connection.create_connection(
        (self._dns_host, self.port),
    ...<2 lines>...
        socket_options=self.socket_options,
    )
  File "/Users/mac/WorkSpace/考研推荐系统/.venv/lib/python3.13/site-packages/urllib3/util/connection.py", line 60, in create_connection
    for res in socket.getaddrinfo(host, port, family, socket.SOCK_STREAM):
               ~~~~~~~~~~~~~~~~~~^^^^^^^^^^^^^^^^^^^^^^^^^^^^^^^^^^^^^^^^
  File "/opt/homebrew/Cellar/python@3.13/3.13.3/Frameworks/Python.framework/Versions/3.13/lib/python3.13/socket.py", line 977, in getaddrinfo
    for res in _socket.getaddrinfo(host, port, family, type, proto, flags):
               ~~~~~~~~~~~~~~~~~~~^^^^^^^^^^^^^^^^^^^^^^^^^^^^^^^^^^^^^^^^
socket.gaierror: [Errno 8] nodename nor servname provided, or not known

The above exception was the direct cause of the following exception:

Traceback (most recent call last):
  File "/Users/mac/WorkSpace/考研推荐系统/.venv/lib/python3.13/site-packages/urllib3/connectionpool.py", line 787, in urlopen
    response = self._make_request(
        conn,
    ...<10 lines>...
        **response_kw,
    )
  File "/Users/mac/WorkSpace/考研推荐系统/.venv/lib/python3.13/site-packages/urllib3/connectionpool.py", line 488, in _make_request
    raise new_e
  File "/Users/mac/WorkSpace/考研推荐系统/.venv/lib/python3.13/site-packages/urllib3/connectionpool.py", line 464, in _make_request
    self._validate_conn(conn)
    ~~~~~~~~~~~~~~~~~~~^^^^^^
  File "/Users/mac/WorkSpace/考研推荐系统/.venv/lib/python3.13/site-packages/urllib3/connectionpool.py", line 1093, in _validate_conn
    conn.connect()
    ~~~~~~~~~~~~^^
  File "/Users/mac/WorkSpace/考研推荐系统/.venv/lib/python3.13/site-packages/urllib3/connection.py", line 704, in connect
    self.sock = sock = self._new_conn()
                       ~~~~~~~~~~~~~~^^
  File "/Users/mac/WorkSpace/考研推荐系统/.venv/lib/python3.13/site-packages/urllib3/connection.py", line 205, in _new_conn
    raise NameResolutionError(self.host, self, e) from e
urllib3.exceptions.NameResolutionError: <urllib3.connection.HTTPSConnection object at 0x110518550>: Failed to resolve 'graduate.swust.edu.cn' ([Errno 8] nodename nor servname provided, or not known)

The above exception was the direct cause of the following exception:

Traceback (most recent call last):
  File "/Users/mac/WorkSpace/考研推荐系统/.venv/lib/python3.13/site-packages/requests/adapters.py", line 667, in send
    resp = conn.urlopen(
        method=request.method,
    ...<9 lines>...
        chunked=chunked,
    )
  File "/Users/mac/WorkSpace/考研推荐系统/.venv/lib/python3.13/site-packages/urllib3/connectionpool.py", line 841, in urlopen
    retries = retries.increment(
        method, url, error=new_e, _pool=self, _stacktrace=sys.exc_info()[2]
    )
  File "/Users/mac/WorkSpace/考研推荐系统/.venv/lib/python3.13/site-packages/urllib3/util/retry.py", line 519, in increment
    raise MaxRetryError(_pool, url, reason) from reason  # type: ignore[arg-type]
    ^^^^^^^^^^^^^^^^^^^^^^^^^^^^^^^^^^^^^^^^^^^^^^^^^^^
urllib3.exceptions.MaxRetryError: HTTPSConnectionPool(host='graduate.swust.edu.cn', port=443): Max retries exceeded with url: / (Caused by NameResolutionError("<urllib3.connection.HTTPSConnection object at 0x110518550>: Failed to resolve 'graduate.swust.edu.cn' ([Errno 8] nodename nor servname provided, or not known)"))

During handling of the above exception, another exception occurred:

Traceback (most recent call last):
  File "/Users/mac/WorkSpace/考研推荐系统/utils/scraper.py", line 270, in fetch_page
    response = requests.get(url, headers=headers, timeout=REQUEST_TIMEOUT, verify=False)
  File "/Users/mac/WorkSpace/考研推荐系统/.venv/lib/python3.13/site-packages/requests/api.py", line 73, in get
    return request("get", url, params=params, **kwargs)
  File "/Users/mac/WorkSpace/考研推荐系统/.venv/lib/python3.13/site-packages/requests/api.py", line 59, in request
    return session.request(method=method, url=url, **kwargs)
           ~~~~~~~~~~~~~~~^^^^^^^^^^^^^^^^^^^^^^^^^^^^^^^^^^
  File "/Users/mac/WorkSpace/考研推荐系统/.venv/lib/python3.13/site-packages/requests/sessions.py", line 589, in request
    resp = self.send(prep, **send_kwargs)
  File "/Users/mac/WorkSpace/考研推荐系统/.venv/lib/python3.13/site-packages/requests/sessions.py", line 703, in send
    r = adapter.send(request, **kwargs)
  File "/Users/mac/WorkSpace/考研推荐系统/.venv/lib/python3.13/site-packages/requests/adapters.py", line 700, in send
    raise ConnectionError(e, request=request)
requests.exceptions.ConnectionError: HTTPSConnectionPool(host='graduate.swust.edu.cn', port=443): Max retries exceeded with url: / (Caused by NameResolutionError("<urllib3.connection.HTTPSConnection object at 0x110518550>: Failed to resolve 'graduate.swust.edu.cn' ([Errno 8] nodename nor servname provided, or not known)"))

During handling of the above exception, another exception occurred:

Traceback (most recent call last):
  File "/Users/mac/WorkSpace/考研推荐系统/.venv/lib/python3.13/site-packages/urllib3/connection.py", line 198, in _new_conn
    sock = connection.create_connection(
        (self._dns_host, self.port),
    ...<2 lines>...
        socket_options=self.socket_options,
    )
  File "/Users/mac/WorkSpace/考研推荐系统/.venv/lib/python3.13/site-packages/urllib3/util/connection.py", line 60, in create_connection
    for res in socket.getaddrinfo(host, port, family, socket.SOCK_STREAM):
               ~~~~~~~~~~~~~~~~~~^^^^^^^^^^^^^^^^^^^^^^^^^^^^^^^^^^^^^^^^
  File "/opt/homebrew/Cellar/python@3.13/3.13.3/Frameworks/Python.framework/Versions/3.13/lib/python3.13/socket.py", line 977, in getaddrinfo
    for res in _socket.getaddrinfo(host, port, family, type, proto, flags):
               ~~~~~~~~~~~~~~~~~~~^^^^^^^^^^^^^^^^^^^^^^^^^^^^^^^^^^^^^^^^
socket.gaierror: [Errno 8] nodename nor servname provided, or not known

The above exception was the direct cause of the following exception:

Traceback (most recent call last):
  File "/Users/mac/WorkSpace/考研推荐系统/.venv/lib/python3.13/site-packages/urllib3/connectionpool.py", line 787, in urlopen
    response = self._make_request(
        conn,
    ...<10 lines>...
        **response_kw,
    )
  File "/Users/mac/WorkSpace/考研推荐系统/.venv/lib/python3.13/site-packages/urllib3/connectionpool.py", line 488, in _make_request
    raise new_e
  File "/Users/mac/WorkSpace/考研推荐系统/.venv/lib/python3.13/site-packages/urllib3/connectionpool.py", line 464, in _make_request
    self._validate_conn(conn)
    ~~~~~~~~~~~~~~~~~~~^^^^^^
  File "/Users/mac/WorkSpace/考研推荐系统/.venv/lib/python3.13/site-packages/urllib3/connectionpool.py", line 1093, in _validate_conn
    conn.connect()
    ~~~~~~~~~~~~^^
  File "/Users/mac/WorkSpace/考研推荐系统/.venv/lib/python3.13/site-packages/urllib3/connection.py", line 704, in connect
    self.sock = sock = self._new_conn()
                       ~~~~~~~~~~~~~~^^
  File "/Users/mac/WorkSpace/考研推荐系统/.venv/lib/python3.13/site-packages/urllib3/connection.py", line 205, in _new_conn
    raise NameResolutionError(self.host, self, e) from e
urllib3.exceptions.NameResolutionError: <urllib3.connection.HTTPSConnection object at 0x1105187d0>: Failed to resolve 'graduate.swust.edu.cn' ([Errno 8] nodename nor servname provided, or not known)

The above exception was the direct cause of the following exception:

Traceback (most recent call last):
  File "/Users/mac/WorkSpace/考研推荐系统/.venv/lib/python3.13/site-packages/requests/adapters.py", line 667, in send
    resp = conn.urlopen(
        method=request.method,
    ...<9 lines>...
        chunked=chunked,
    )
  File "/Users/mac/WorkSpace/考研推荐系统/.venv/lib/python3.13/site-packages/urllib3/connectionpool.py", line 841, in urlopen
    retries = retries.increment(
        method, url, error=new_e, _pool=self, _stacktrace=sys.exc_info()[2]
    )
  File "/Users/mac/WorkSpace/考研推荐系统/.venv/lib/python3.13/site-packages/urllib3/util/retry.py", line 519, in increment
    raise MaxRetryError(_pool, url, reason) from reason  # type: ignore[arg-type]
    ^^^^^^^^^^^^^^^^^^^^^^^^^^^^^^^^^^^^^^^^^^^^^^^^^^^
urllib3.exceptions.MaxRetryError: HTTPSConnectionPool(host='graduate.swust.edu.cn', port=443): Max retries exceeded with url: / (Caused by NameResolutionError("<urllib3.connection.HTTPSConnection object at 0x1105187d0>: Failed to resolve 'graduate.swust.edu.cn' ([Errno 8] nodename nor servname provided, or not known)"))

During handling of the above exception, another exception occurred:

Traceback (most recent call last):
  File "/Users/mac/WorkSpace/考研推荐系统/utils/scraper.py", line 270, in fetch_page
    response = requests.get(url, headers=headers, timeout=REQUEST_TIMEOUT, verify=False)
  File "/Users/mac/WorkSpace/考研推荐系统/.venv/lib/python3.13/site-packages/requests/api.py", line 73, in get
    return request("get", url, params=params, **kwargs)
  File "/Users/mac/WorkSpace/考研推荐系统/.venv/lib/python3.13/site-packages/requests/api.py", line 59, in request
    return session.request(method=method, url=url, **kwargs)
           ~~~~~~~~~~~~~~~^^^^^^^^^^^^^^^^^^^^^^^^^^^^^^^^^^
  File "/Users/mac/WorkSpace/考研推荐系统/.venv/lib/python3.13/site-packages/requests/sessions.py", line 589, in request
    resp = self.send(prep, **send_kwargs)
  File "/Users/mac/WorkSpace/考研推荐系统/.venv/lib/python3.13/site-packages/requests/sessions.py", line 703, in send
    r = adapter.send(request, **kwargs)
  File "/Users/mac/WorkSpace/考研推荐系统/.venv/lib/python3.13/site-packages/requests/adapters.py", line 700, in send
    raise ConnectionError(e, request=request)
requests.exceptions.ConnectionError: HTTPSConnectionPool(host='graduate.swust.edu.cn', port=443): Max retries exceeded with url: / (Caused by NameResolutionError("<urllib3.connection.HTTPSConnection object at 0x1105187d0>: Failed to resolve 'graduate.swust.edu.cn' ([Errno 8] nodename nor servname provided, or not known)"))
